<?xml version="1.0" encoding="utf-8"?>
<robot name="simple_pendulum">
    <link name="base">
        <visual>
            <origin xyz="0 0 0" rpy="0 0 0" />
            <geometry>
                <box size="0.05 0.05 0.05"/>
            </geometry>
            <material name="">
                <color rgba="0 0 0 1" />
            </material>
        </visual>
    </link>
    <link name="body">
        <visual>
            <origin xyz="0 0 0.15" rpy="0 0 0" />
            <geometry>
                <box size="0.025 0.025 0.25"/>
            </geometry>
            <material name="">
                <color rgba="1 0 0 1" />
            </material>
        </visual>
    </link>
    <joint name="joint" type="revolute">
        <origin xyz="0 0 0" rpy="0 0 0" />
        <parent link="base" />
        <child link="body" />
        <axis xyz="1 0 0" />
        <limit lower="0.0" upper="6.28" effort="0" velocity="1.0" />
        <dynamics damping="0.05" />
    </joint>
    <link name="tip">
        <visual>
            <origin xyz="0 0 0" rpy="0 0 0" />
            <geometry>
                <box size="0.05 0.05 0.05"/>
            </geometry>
            <material name="">
                <color rgba="1 0 0 1" />
            </material>
        </visual>
    </link>
    <joint name="fixed_tip" type="fixed">
        <origin xyz="0 0 0.25" rpy="0 0 0" />
        <parent link="body" />
        <child link="tip" />
        <axis xyz="1 0 0" />
    </joint>
</robot>
